10/23/2023 22:52:57 - WARNING - discord.client -   PyNaCl is not installed, voice will NOT be supported
10/23/2023 22:52:57 - DEBUG - discord.client -   on_ready has successfully been registered as an event
10/23/2023 22:52:57 - DEBUG - asyncio -   Using proactor: IocpProactor
10/23/2023 22:52:57 - INFO - discord.client -   logging in using static token
10/23/2023 22:53:20 - INFO - discord.gateway -   Shard ID None has connected to Gateway (Session ID: f6d062cd711651d0e2dd8bab67a5521c).
10/23/2023 22:53:22 - INFO - BOT -   Bot loaded extensions on_join_handler.py
10/23/2023 22:53:22 - INFO - BOT -   Bot loaded extensions presence_manager.py
10/23/2023 22:53:22 - ERROR - BOT -   Extension 'Bot.cogs.__init__' has no 'setup' function.
10/23/2023 22:54:13 - ERROR - discord.ext.commands.bot -   Ignoring exception in command presence
Traceback (most recent call last):
  File "C:\Users\Aaroegun\AppData\Roaming\Python\Python311\site-packages\discord\ext\commands\core.py", line 235, in wrapped
    ret = await coro(*args, **kwargs)
          ^^^^^^^^^^^^^^^^^^^^^^^^^^^
  File "c:\Users\Aaroegun\Desktop\Techrise-Visionary-bot\Bot\cogs\presence_manager.py", line 42, in presence
    self.change_presence.start()
  File "C:\Users\Aaroegun\AppData\Roaming\Python\Python311\site-packages\discord\ext\tasks\__init__.py", line 392, in start
    raise RuntimeError('Task is already launched and is not completed.')
RuntimeError: Task is already launched and is not completed.

The above exception was the direct cause of the following exception:

Traceback (most recent call last):
  File "C:\Users\Aaroegun\AppData\Roaming\Python\Python311\site-packages\discord\ext\commands\bot.py", line 1350, in invoke
    await ctx.command.invoke(ctx)
  File "C:\Users\Aaroegun\AppData\Roaming\Python\Python311\site-packages\discord\ext\commands\core.py", line 1029, in invoke
    await injected(*ctx.args, **ctx.kwargs)  # type: ignore
    ^^^^^^^^^^^^^^^^^^^^^^^^^^^^^^^^^^^^^^^
  File "C:\Users\Aaroegun\AppData\Roaming\Python\Python311\site-packages\discord\ext\commands\core.py", line 244, in wrapped
    raise CommandInvokeError(exc) from exc
discord.ext.commands.errors.CommandInvokeError: Command raised an exception: RuntimeError: Task is already launched and is not completed.
